<?xml version="1.0" encoding="UTF-8"?>
<testng-results ignored="1" total="2" passed="0" failed="1" skipped="0">
  <reporter-output>
  </reporter-output>
  <suite started-at="2023-07-22T10:46:58 IST" name="Default suite" finished-at="2023-07-22T10:47:00 IST" duration-ms="2401">
    <groups>
    </groups>
    <test started-at="2023-07-22T10:46:58 IST" name="Default test" finished-at="2023-07-22T10:47:00 IST" duration-ms="2401">
      <class name="github_test_cases.github_testcases">
        <test-method signature="CreateRepoDynamic()[pri:0, instance:github_test_cases.github_testcases@54a7079e]" started-at="2023-07-22T10:46:58 IST" name="CreateRepoDynamic" finished-at="2023-07-22T10:47:00 IST" duration-ms="2353" status="FAIL">
          <exception class="java.lang.AssertionError">
            <message>
              <![CDATA[expected [null] but found [Shashidhar_Restassured_framework_repo]]]>
            </message>
            <full-stacktrace>
              <![CDATA[java.lang.AssertionError: expected [null] but found [Shashidhar_Restassured_framework_repo]
at org.testng.Assert.fail(Assert.java:110)
at org.testng.Assert.failNotEquals(Assert.java:1577)
at org.testng.Assert.assertEqualsImpl(Assert.java:149)
at org.testng.Assert.assertEquals(Assert.java:131)
at org.testng.Assert.assertEquals(Assert.java:655)
at org.testng.Assert.assertEquals(Assert.java:665)
at github_test_cases.github_testcases.CreateRepoDynamic(github_testcases.java:51)
at java.base/jdk.internal.reflect.NativeMethodAccessorImpl.invoke0(Native Method)
at java.base/jdk.internal.reflect.NativeMethodAccessorImpl.invoke(NativeMethodAccessorImpl.java:77)
at java.base/jdk.internal.reflect.DelegatingMethodAccessorImpl.invoke(DelegatingMethodAccessorImpl.java:43)
at java.base/java.lang.reflect.Method.invoke(Method.java:568)
at org.testng.internal.invokers.MethodInvocationHelper.invokeMethod(MethodInvocationHelper.java:139)
at org.testng.internal.invokers.TestInvoker.invokeMethod(TestInvoker.java:677)
at org.testng.internal.invokers.TestInvoker.invokeTestMethod(TestInvoker.java:221)
at org.testng.internal.invokers.MethodRunner.runInSequence(MethodRunner.java:50)
at org.testng.internal.invokers.TestInvoker$MethodInvocationAgent.invoke(TestInvoker.java:969)
at org.testng.internal.invokers.TestInvoker.invokeTestMethods(TestInvoker.java:194)
at org.testng.internal.invokers.TestMethodWorker.invokeTestMethods(TestMethodWorker.java:148)
at org.testng.internal.invokers.TestMethodWorker.run(TestMethodWorker.java:128)
at java.base/java.util.ArrayList.forEach(ArrayList.java:1511)
at org.testng.TestRunner.privateRun(TestRunner.java:829)
at org.testng.TestRunner.run(TestRunner.java:602)
at org.testng.SuiteRunner.runTest(SuiteRunner.java:437)
at org.testng.SuiteRunner.runSequentially(SuiteRunner.java:431)
at org.testng.SuiteRunner.privateRun(SuiteRunner.java:391)
at org.testng.SuiteRunner.run(SuiteRunner.java:330)
at org.testng.SuiteRunnerWorker.runSuite(SuiteRunnerWorker.java:52)
at org.testng.SuiteRunnerWorker.run(SuiteRunnerWorker.java:95)
at org.testng.TestNG.runSuitesSequentially(TestNG.java:1256)
at org.testng.TestNG.runSuitesLocally(TestNG.java:1176)
at org.testng.TestNG.runSuites(TestNG.java:1099)
at org.testng.TestNG.run(TestNG.java:1067)
at org.testng.remote.AbstractRemoteTestNG.run(AbstractRemoteTestNG.java:115)
at org.testng.remote.RemoteTestNG.initAndRun(RemoteTestNG.java:251)
at org.testng.remote.RemoteTestNG.main(RemoteTestNG.java:77)
]]>
            </full-stacktrace>
          </exception> <!-- java.lang.AssertionError -->
          <reporter-output>
          </reporter-output>
        </test-method> <!-- CreateRepoDynamic -->
      </class> <!-- github_test_cases.github_testcases -->
    </test> <!-- Default test -->
  </suite> <!-- Default suite -->
</testng-results>
